Workbook

Sheet Answer Key
A1: LMT Places Simulator — Built-in Answer Key (TRAINERS ONLY)
A2: Approve cases are real Kerala Tourism-registered homestays (data checked Oct 2026 — re-check before each wave). Alias = well-known hotels already on Tripadvisor. Unverifiable / Tier 2 names are invented on purpose. "|" separates accepted alternatives; BLANK = must be left empty.
A4: Case ID | B4: Day | C4: Q# | D4: Feed Name | E4: Correct Name | F4: Correct Parent (City, Region, Country) | G4: Correct Action | H4: Correct Reason | I4: Correct Street One | J4: Correct Street Two | K4: Correct Postal Code | L4: Correct Phone | M4: Correct Email | N4: Correct URL | O4: Correct Accommodation Type | P4: Correct Rooms | Q4: Correct Latitude | R4: Correct Longitude | S4: Geo Tolerance (m) | T4: Feed Latitude (start pin) | U4: Feed Longitude | V4: Coaching Note | W4: Reference Link (trainers only)
A5: D1-01 | B5: 1 | C5: 1 | D5: SNOW MOON HOMESTAY | E5: Snow Moon Homestay | F5: Munnar, Idukki District, Kerala, India | G5: Approve | H5: New property – verified across sources | I5: Pattamthanath House, Chithirapuram | Pattamthanath House | K5: 685565 | L5: +91 88480 19141 | M5: snowmoonhomestay@gmail.com | info@snowmoonhomestay.com | N5: http://www.snowmoonhomestay.com | BLANK | O5: Guest House | Q5: 10.028392 | R5: 77.045577 | S5: 300 | T5: 10.0402 | U5: 77.0571 | V5: Feed was in ALL CAPS, the phone had no +91 and the pin was 1.7 km off. It is a homestay, so Guest House, not Hotel. Chithirapuram is a neighbourhood — the parent is Munnar. Source: the Kerala Tourism listing, the official site and Google Maps. | W5: https://www.keralatourism.org/homestays/snow-moon-homestay/4038
A6: D1-02 | B6: 1 | C6: 2 | D6: Green Horizon Home Stay | E6: Green Horizon Homestay | F6: Kochi (Cochin), Ernakulam District, Kerala, India | G6: Approve | H6: New property – verified across sources | I6: Fort Nagar, Fort Kochi | Fort Nagar | K6: 682001 | L6: +91 88910 77232 | M6: greenhorizonstay@gmail.com | N6: http://www.greenhorizonstay.com | BLANK | O6: Guest House | Q6: 9.966791 | R6: 76.244514 | S6: 250 | T6: 33.5597 | U6: 133.5311 | V6: The feed pin landed in Kochi, JAPAN. Always check the country when you pick a parent. Fort Kochi is a neighbourhood of Kochi (Cochin), Kerala. | W6: https://www.keralatourism.org/homestays/green-horizon-homestay/8482
A7: D1-03 | B7: 1 | C7: 3 | D7: Kerala Spices Homestay Thekkady | E7: Kerala Spices Homestay | F7: Kumily (Thekkady), Idukki District, Kerala, India | G7: Approve | H7: New property – verified across sources | I7: Kollaparambil House, Valiyakandam | Kollaparambil House | J7: Valiyakandam | BLANK | K7: 685509 | L7: +91 99473 30134 | M7: keralaspiceshomestay@gmail.com | N7: http://www.keralaspiceshomestay.com | BLANK | O7: Guest House | Q7: 9.610758 | R7: 77.161763 | S7: 300 | T7: 9.604 | U7: 77.168 | V7: Don't keep a city the feed added to the name ("…Thekkady") unless the property uses it. Thekkady sits inside Kumily — pick "Kumily (Thekkady)". | W7: https://www.keralatourism.org/homestays/kerala-spices-homestay/8592
A8: D1-04 | B8: 1 | C8: 4 | D8: BOUGAINVILLEA HOMESTAY | E8: Bougainvillea Homestay | F8: Varkala, Thiruvananthapuram District, Kerala, India | G8: Approve | H8: New property – verified across sources | I8: K N Vihar, North Cliff Helipad Road | KN Vihar, North Cliff Helipad Road | K8: 695141 | L8: +91 85907 94534 | +91 90740 58901 | M8: bougainvilleahomestays@gmail.com | N8: http://bougainvilleahomestays.in | BLANK | O8: Guest House | Q8: 8.737694 | R8: 76.706133 | S8: 250 | T8: 8.7379 | U8: 76.7163 | V8: ALL CAPS name and street must be converted to proper case. Two phone numbers exist — either one in +91 format is fine. | W8: https://www.keralatourism.org/homestays/bougainvillea-homestay/7044
A9: D1-05 | B9: 1 | C9: 5 | D9: Ananda Home Stay Wayanad | E9: Ananda Homestay | F9: Ambalavayal, Wayanad District, Kerala, India | G9: Approve | H9: New property – verified across sources | I9: Nellarachal, Ambalavayal | Nellarachal | K9: 673593 | L9: +91 97444 45288 | +91 98959 90948 | M9: anandawayanad@gmail.com | drlijikrishnan@gmail.com | N9: https://www.anandawayanad.com | O9: Guest House | P9: 4 | Q9: 11.595285 | R9: 76.184797 | S9: 300 | T9: 11.6103 | U9: 76.083 | V9: The feed said Kalpetta and 6 rooms. The homestay's own description says four guest rooms, and it is in Ambalavayal, about 11 km away. The property's own words beat the feed. | W9: https://www.keralatourism.org/homestays/ananda-homestay/6508
A10: D1-06 | B10: 1 | C10: 6 | D10: Royal Mist Homestay | E10: Royal Mist | Royal Mist Homestay | F10: Munnar, Idukki District, Kerala, India | G10: Approve | H10: New property – verified across sources | I10: Chithirapuram | Chithirapuram, Munnar | K10: 685565 | L10: +91 94954 44123 | +91 94470 31814 | M10: royalmistmunnar@gmail.com | N10: http://www.royalmist.in | BLANK | O10: Guest House | Q10: 10.030762 | R10: 77.037892 | S10: 300 | T10: 10.0889 | U10: 77.0595 | V10: The feed pin sat in Munnar town centre, about 6.5 km from the property in Chithirapuram. Re-pin from Google Maps or the Kerala Tourism map. | W10: https://www.keralatourism.org/homestays/royal-mist/3831
A11: D1-07 | B11: 1 | C11: 7 | D11: Thayil Kadaloram Homestay | E11: Thayil Kadaloram Homestay | F11: Kovalam, Thiruvananthapuram District, Kerala, India | G11: Approve | H11: New property – verified across sources | I11: Beach Road | Beach Road, Kovalam | K11: 695527 | L11: +91 471 248 1934 | +91 73066 63669 | M11: thayilkadaloram@gmail.com | N11: BLANK | O11: Guest House | Q11: 8.390082 | R11: 76.976099 | S11: 250 | T11: 12.79 | U11: 80.254 | V11: There are two Kovalams: the beach town in Kerala and Kovalam (Covelong) near Chennai — the feed pin was in Tamil Nadu. Landline 0471… becomes +91 471…. No website exists, so URL stays blank. | W11: https://www.keralatourism.org/homestays/thayil-kadaloram-homestay/6232
A12: D1-08 | B12: 1 | C12: 8 | D12: Kumarakom Lake Resort & Ayurveda Spa | E12: Kumarakom Lake Resort | F12: Kumarakom, Kottayam District, Kerala, India | G12: Alias | H12: Existing Tripadvisor listing – add feed name as alias | O12: Resort | Q12: 9.6176 | R12: 76.4278 | T12: 9.6176 | U12: 76.4278 | V12: A famous resort that has been on Tripadvisor for years. The feed just added words to the name. Search tripadvisor.com, open the existing listing, paste its link and add the feed name as an alias — never create a duplicate.
A13: D1-09 | B13: 1 | C13: 9 | D13: Mattancherry Palace Heritage Stay | E13: Mattancherry Palace | F13: Kochi (Cochin), Ernakulam District, Kerala, India | G13: Reject | H13: Not an accommodation | O13: N/A | Q13: 9.9583 | R13: 76.2593 | T13: 9.9583 | U13: 76.2593 | V13: Mattancherry Palace (the Dutch Palace) is a museum. Nobody can book a room there — a monument is not an accommodation. Reject.
A14: D1-10 | B14: 1 | C14: 10 | D14: Amberleaf Spice Court | E14: Amberleaf Spice Court | F14: Kumily (Thekkady), Idukki District, Kerala, India | G14: Reject | H14: Unverifiable – no evidence the property exists | Q14: 9.608 | R14: 77.166 | T14: 9.608 | U14: 77.166 | V14: Google, Google Maps, Facebook, Instagram and Kerala Tourism show nothing for this name, and the feed gives no phone or website. With zero evidence the property exists, Reject as Unverifiable.
A15: D2-01 | B15: 2 | C15: 1 | D15: The Haven | E15: The Haven Munnar | F15: Munnar, Idukki District, Kerala, India | G15: Approve | H15: New property – verified across sources | I15: 10/40, Thokkupara Junction | 10/40 Thokkupara Junction | K15: 685565 | L15: +91 4865 263617 | +91 94000 37623 | +91 83018 83617 | M15: thehavenmunnar@gmail.com | agilehomestay@gmail.com | N15: http://www.thehavenmunnar.com | BLANK | O15: Guest House | Q15: 10.025238 | R15: 77.026144 | S15: 250 | T15: 10.0251 | U15: 77.0263 | V15: Here the city IS part of the official name: "The Haven Munnar". Expand "JN" to Junction, and convert 04865… to +91 4865…. | W15: https://www.keralatourism.org/homestays/the-haven-munnar/4071
A16: D2-02 | B16: 2 | C16: 2 | D16: LINN VIEW HOMESTAY | E16: Linn View Home Stay Munnar | Linn View Home Stay | Linn View Homestay | F16: Munnar, Idukki District, Kerala, India | G16: Approve | H16: New property – verified across sources | I16: Mathalipara House, Anaviratty | Mathalipara House | K16: 685561 | L16: +91 94467 43768 | +91 95447 43767 | M16: linviewhomestay@gmail.com | N16: BLANK | O16: Guest House | Q16: 10.006629 | R16: 77.006671 | S16: 300 | T16: 10.0066 | U16: 77.0067 | V16: The feed sent Munnar town's PIN (685612). The property is in Anaviratty — PIN 685561. Reject wrong feed values with ✖ instead of copying them. | W16: https://www.keralatourism.org/homestays/linn-view-home-stay-munnar/6228
A17: D2-03 | B17: 2 | C17: 3 | D17: Hill Mist Homestay Kumily | E17: Hill Mist | Hill Mist Homestay | F17: Kumily (Thekkady), Idukki District, Kerala, India | G17: Approve | H17: New property – verified across sources | I17: 1st Mile, Kumily Munnar Road | 1st Mile Kumily To Munnar Road | First Mile, Kumily Munnar Road | K17: 685509 | L17: +91 98465 79205 | M17: hillmist.booking@gmail.com | N17: BLANK | O17: Guest House | Q17: 9.619458 | R17: 77.162006 | S17: 200 | T17: 9.6195 | U17: 77.162 | V17: Remove the city the feed appended to the name and expand "Rd" to Road. No website exists — leave URL blank. | W17: https://www.keralatourism.org/homestays/hill-mist/6835
A18: D2-04 | B18: 2 | C18: 4 | D18: Angel Homestay | E18: Angel Homestay | F18: Alappuzha (Alleppey), Alappuzha District, Kerala, India | G18: Approve | H18: New property – verified across sources | I18: Thekkummuriyil, Punnapra | Thekkummuriyil | J18: Punnapra | BLANK | K18: 688004 | L18: +91 86066 06451 | M18: angelhomestayalpy4@gmail.com | bozkojone@gmail.com | N18: BLANK | O18: Guest House | Q18: 9.45074 | R18: 76.34122 | S18: 300 | T18: 9.4981 | U18: 76.3388 | V18: Wrong PIN in the feed (688001 is Alappuzha town). The homestay is in Punnapra, PIN 688004, about 5 km south. | W18: https://www.keralatourism.org/homestays/angel-homestay/6758
A19: D2-05 | B19: 2 | C19: 5 | D19: PADDY & CANAL HOMESTAY | E19: Paddy N Canal Homestay | Paddy 'N' Canal Homestay | F19: Alappuzha (Alleppey), Alappuzha District, Kerala, India | G19: Approve | H19: New property – verified across sources | I19: Near KSRTC Bus Stand | Near Alleppey KSRTC Bus Stand | J19: East of Alappuzha Fire Station | BLANK | K19: 688011 | L19: +91 62826 44098 | +91 96459 63812 | M19: paddyncanal@gmail.com | robinpsunil2002@gmail.com | N19: BLANK | O19: Guest House | Q19: 9.4982 | R19: 76.349674 | S19: 200 | T19: 9.4982 | U19: 76.3497 | V19: The feed claimed an OYO brand — no OYO page lists this homestay, so Brand must stay blank. Write the name the way the property does ("Paddy N Canal"), and drop the 0 before the mobile number. | W19: https://www.keralatourism.org/homestays/paddy-n-canal-homestay/6764
A20: D2-06 | B20: 2 | C20: 6 | D20: Illusion Homestay | E20: Illusion Homestay | F20: Varkala, Thiruvananthapuram District, Kerala, India | G20: Approve | H20: New property – verified across sources | I20: Near Devaswom Campshed, Janardhanapuram | Near Devaswom Campshed, West of Janardhana Swamy Temple | West of Janardhana Swamy Temple, Janardhanapuram | K20: 695141 | L20: +91 94462 37733 | +91 94460 89494 | M20: illusion.varkala@gmail.com | vijayakumarg1963@gmail.com | N20: BLANK | O20: Guest House | Q20: 8.73197 | R20: 76.70764 | S20: 200 | T20: 8.732 | U20: 76.7076 | V20: The feed crammed two phone numbers into one field. Enter ONE number in +91 format. | W20: https://www.keralatourism.org/homestays/illusion-homestay/7271
A21: D2-07 | B21: 2 | C21: 7 | D21: Blue Lagoon Munroe Homestay | E21: Blue Lagoon Mundro Homestay | Blue Lagoon Munroe Homestay | Blue Lagoon Munroe | F21: Munroe Island, Kollam District, Kerala, India | G21: Approve | H21: New property – verified across sources | I21: Muttom, East Kallada | Muttom | K21: 691502 | L21: +91 98463 26475 | M21: info@bluelagoonmunroe.com | N21: https://bluelagoonmunroe.com | O21: Guest House | Q21: 8.992646 | R21: 76.643463 | S21: 300 | T21: 8.8932 | U21: 76.6141 | V21: The feed pin was in Kollam city, 11 km away. Munroe Island is its own parent geo. | W21: https://www.keralatourism.org/homestays/blue-lagoon-mundro-homestay/8967
A22: D2-08 | B22: 2 | C22: 8 | D22: CGH Earth Brunton Boatyard Hotel Fort Kochi | E22: Brunton Boatyard | F22: Kochi (Cochin), Ernakulam District, Kerala, India | G22: Alias | H22: Existing Tripadvisor listing – add feed name as alias | O22: Hotel | Q22: 9.9666 | R22: 76.2427 | T22: 9.9666 | U22: 76.2427 | V22: Brunton Boatyard is a long-established Fort Kochi hotel already on Tripadvisor. "CGH Earth … Hotel Fort Kochi" is just brand + city padding. Paste the existing listing link and add the alias.
A23: D2-09 | B23: 2 | C23: 9 | D23: Kathakali Centre Guest Rooms | E23: Kerala Kathakali Centre | F23: Kochi (Cochin), Ernakulam District, Kerala, India | G23: Reject | H23: Not an accommodation | O23: N/A | Q23: 9.9658 | R23: 76.2421 | T23: 9.9658 | U23: 76.2421 | V23: The Kerala Kathakali Centre is a performance and cultural venue (shows, classes). It has no rooms for guests — Reject as not an accommodation.
A24: D2-10 | B24: 2 | C24: 10 | D24: Goldcoast Sapphire Villas | E24: Goldcoast Sapphire Villas | F24: Cherai, Vypin Island, Ernakulam District, Kerala, India | G24: Tier 2 | H24: Suspected fraud / scam indicators | O24: Resort | Q24: 10.1418 | R24: 76.178 | T24: 10.1418 | U24: 76.178 | V24: Nothing exists online, AND the request itself carries scam signals: 100% advance to a personal UPI ID, WhatsApp-only contact, scam votes. That is fraud → Tier 2, never a simple Reject.
A25: D3-01 | B25: 3 | C25: 1 | D25: Signature Homestay | E25: Signature Homestay | F25: Munnar, Idukki District, Kerala, India | Adimali, Idukki District, Kerala, India | G25: Approve | H25: New property – verified across sources | I25: Vayanasaala Road, Kunchithanny | Vayanasaala Road | K25: 685565 | L25: +91 94478 21288 | M25: suryashibu75@gmail.com | N25: BLANK | O25: Guest House | Q25: 10.019096 | R25: 77.062858 | S25: 300 | T25: 10.0889 | U25: 77.0595 | V25: Kunchithanny isn't a parent geo — use the nearest real one (Munnar). The feed pin was in Munnar town, 7.7 km north of the property. | W25: https://www.keralatourism.org/homestays/signature-homestay/6378
A26: D3-02 | B26: 3 | C26: 2 | D26: GREENSHORE VILLA VAGAMON | E26: Greenshore | Greenshore Villa | F26: Vagamon, Idukki District, Kerala, India | G26: Approve | H26: New property – verified across sources | I26: 52A Kalathil, Valacode | 52A Kalathil | J26: Opposite St George Malankara Church, Valacode | Valacode | BLANK | K26: 685505 | L26: +91 94474 87194 | M26: vagamon@greenshorevilla.com | shiju@greenshorevilla.com | N26: http://www.greenshorevilla.com | O26: Guest House | Q26: 9.72082 | R26: 76.97348 | S26: 300 | T26: 9.6862 | U26: 76.9058 | V26: The feed URL had no http:// — fix it. The pin sat 8 km away in Vagamon town; the property is in Valacode. | W26: https://www.keralatourism.org/homestays/greenshore/7757
A27: D3-03 | B27: 3 | C27: 3 | D27: Mangal Caverns Homestay | E27: Mangal Caverns Homestay | F27: Vagamon, Idukki District, Kerala, India | G27: Approve | H27: New property – verified across sources | I27: Valacode | Valacode, Vagamon | K27: 685505 | L27: +91 94964 28060 | +91 90744 87880 | M27: varghesemangalathil@gmail.com | N27: BLANK | O27: Guest House | Q27: 9.73092 | R27: 76.98665 | S27: 300 | T27: 9.6862 | U27: 76.9058 | V27: Same feed pin as the last case — feeds often drop every property on the town centre. Always move the pin to the property. | W27: https://www.keralatourism.org/homestays/mangal-caverns-homestay/6752
A28: D3-04 | B28: 3 | C28: 4 | D28: Kalariyullathil Homestay | E28: Kalariyullathil Homestay | F28: Payyoli, Kozhikode District, Kerala, India | Kozhikode (Calicut), Kozhikode District, Kerala, India | G28: Approve | H28: New property – verified across sources | I28: Payyoli-Perambra Road, Kizhur | Behind BJP Maraar Office, Payyoli-Perambra Road | Payyoli Perambra Road | K28: 673522 | L28: +91 97279 31861 | M28: jeejabai_kp@yahoo.com | annajk3@gmail.com | N28: BLANK | O28: Guest House | Q28: 11.523667 | R28: 75.638058 | S28: 300 | T28: 11.2588 | U28: 75.7804 | V28: An Airbnb link is NOT an official website — the URL must stay blank. The feed pin was in Kozhikode city, 33 km from Payyoli. | W28: https://www.keralatourism.org/homestays/kalariyullathil-homestay/6659
A29: D3-05 | B29: 3 | C29: 5 | D29: Dakshin Ayodhya Homestay | E29: Dakshin Ayodhya Homestay | F29: Thrissur, Thrissur District, Kerala, India | G29: Approve | H29: New property – verified across sources | I29: 16/491, Chethikattil, Velu Amman Padi Junction | 16/491, Chethikattil | J29: Near SNMHS School, Chazhur | Chazhur | BLANK | K29: 680571 | L29: +91 94959 73070 | +91 94463 72070 | M29: dakshinayodhya@gmail.com | dika.23@gmail.com | N29: BLANK | O29: Guest House | Q29: 10.43693 | R29: 76.14976 | S29: 300 | T29: 10.7905 | U29: 78.7047 | V29: "Trichur" is the old name of Thrissur (Kerala). The feed pin went to Trichy (Tiruchirappalli) in Tamil Nadu — 280 km away. | W29: https://www.keralatourism.org/homestays/dakshin-ayodhya-homestay/7229
A30: D3-06 | B30: 3 | C30: 6 | D30: Pannadikadu Homestay | E30: Pannadikadu Homestay | F30: Muthalamada, Palakkad District, Kerala, India | Palakkad, Palakkad District, Kerala, India | G30: Approve | H30: New property – verified across sources | I30: 9/312, Thumbassery House, Chemmanampathy | 9/312, T.House Thumbassery, Chemmanampathy | Thumbassery, Chemmanampathy | K30: 678507 | L30: +91 95392 84669 | +91 4923 294049 | M30: pannadikadu@gmail.com | geothumpassery@gmail.com | N30: https://pannadikaduhomestay.com | O30: Guest House | P30: 2 | Q30: 10.560042 | R30: 76.829929 | S30: 300 | T30: 10.7867 | U30: 76.6548 | V30: The feed pin was in Palakkad town, 30 km away. The homestay is two cottages near Muthalamada — rooms = 2. | W30: https://www.keralatourism.org/homestays/pannadikadu-homestay/7301
A31: D3-07 | B31: 3 | C31: 7 | D31: Spice Village CGH Earth Kumily | E31: Spice Village | F31: Kumily (Thekkady), Idukki District, Kerala, India | G31: Alias | H31: Existing Tripadvisor listing – add feed name as alias | O31: Resort | Q31: 9.6036 | R31: 77.1633 | T31: 9.6036 | U31: 77.1633 | V31: Spice Village is a well-known Thekkady resort already on Tripadvisor. Brand and town were padded into the feed name. Alias it.
A32: D3-08 | B32: 3 | C32: 8 | D32: Napier Museum | E32: Napier Museum | F32: Thiruvananthapuram (Trivandrum), Thiruvananthapuram District, Kerala, India | G32: Reject | H32: Not an accommodation | O32: N/A | Q32: 8.5089 | R32: 76.9554 | T32: 8.5089 | U32: 76.9554 | V32: The feed typed a famous museum as a Hotel. A museum is an attraction, not an accommodation — Reject.
A33: D3-09 | B33: 3 | C33: 9 | D33: Saltwind Heritage Inn | E33: Saltwind Heritage Inn | F33: Kannur, Kannur District, Kerala, India | G33: Reject | H33: Unverifiable – no evidence the property exists | Q33: 11.8697 | R33: 75.3632 | T33: 11.8697 | U33: 75.3632 | V33: No website, no Maps pin, no social pages, no Kerala Tourism entry — and the feed has no contact details. Unverifiable → Reject.
A34: D3-10 | B34: 3 | C34: 10 | D34: Royal Raft Houseboats | E34: Royal Raft Houseboats | F34: Kumarakom, Kottayam District, Kerala, India | G34: Tier 2 | H34: Suspected fraud / scam indicators | O34: Specialty Lodging | Q34: 9.6094 | R34: 76.435 | T34: 9.6094 | U34: 76.435 | V34: Pay-first with the location revealed only after payment, plus a scam report — classic booking-fraud pattern. Tier 2.
A35: D4-01 | B35: 4 | C35: 1 | D35: KACHIPRATH HOMESTAY | E35: Kachiprath Homestay | F35: Kannur, Kannur District, Kerala, India | G35: Approve | H35: New property – verified across sources | I35: Makreri | Makreri, Kannur | L35: +91 95624 45116 | M35: leenakachiprath@gmail.com | N35: BLANK | O35: Guest House | Q35: 11.850457 | R35: 75.493033 | S35: 400 | T35: 11.8745 | U35: 75.3704 | V35: A small rural homestay with very little online — the Kerala Tourism listing and Maps are your main sources. Pin it where the map shows it, 13 km inland from Kannur town. | W35: https://www.keralatourism.org/homestays/kachiprath-homestay/8427
A36: D4-02 | B36: 4 | C36: 2 | D36: Happy Valley Homestay | E36: Happy Valley Home Stay | Happy Valley Homestay | F36: Taliparamba, Kannur District, Kerala, India | Kannur, Kannur District, Kerala, India | G36: Approve | H36: New property – verified across sources | I36: Poomangalam | Poomangalam, Kannur | L36: +91 89210 07335 | M36: varunthekkumbad@gmail.com | N36: BLANK | O36: Guest House | Q36: 12.058251 | R36: 75.400833 | S36: 400 | T36: 11.8745 | U36: 75.3704 | V36: The feed called it a Resort; it is a registered homestay → Guest House. Poomangalam is near Taliparamba, 20 km north of Kannur town. | W36: https://www.keralatourism.org/homestays/happy-valley-home-stay/8789
A37: D4-03 | B37: 4 | C37: 3 | D37: Meadows: Kannurs Serene Retreat | E37: Meadows: Kannur's Serene Retreat Homestay | Meadows: Kannurs Serene Retreat Homestay | Meadows Homestay | Meadows | F37: Kannur, Kannur District, Kerala, India | G37: Approve | H37: New property – verified across sources | I37: Opposite Income Tax Office, Kannothumchal | Kannothumchal | J37: Chovva | BLANK | K37: 670006 | L37: +91 80753 89103 | M37: akmalyasheen@gmail.com | N37: BLANK | O37: Guest House | Apartment Hotel | P37: 2 | Q37: 11.873109 | R37: 75.391356 | S37: 250 | T37: 11.8745 | U37: 75.3704 | V37: A two-bedroom home in Kannothumchal (Chovva) — rooms = 2. Landmarks such as "opposite Income Tax Office" go with the street. | W37: https://www.keralatourism.org/homestays/meadows-kannurs-serene-retreat-homestay/6952
A38: D4-04 | B38: 4 | C38: 4 | D38: Spice Garden Residency | E38: Spice Garden Residency | F38: Athirappilly, Thrissur District, Kerala, India | G38: Approve | H38: New property – verified across sources | I38: Vettilappara 15, Pariyaram | Vettilappara 15 | Vettilappara | K38: 680721 | L38: +91 94951 63602 | M38: spicegardenresidency@gmail.com | N38: BLANK | O38: Guest House | Q38: 10.291252 | R38: 76.506007 | S38: 300 | T38: 10.285 | U38: 76.5694 | V38: "Residency" sounds like a hotel, but it is registered as a homestay → Guest House. The feed pin sat at the waterfall, 7 km away. | W38: https://www.keralatourism.org/homestays/spice-garden-residency/6363
A39: D4-05 | B39: 4 | C39: 5 | D39: Aathira Agri Homes | E39: Aathira Agri-Homes | Aathira Agri Homes | F39: Chalakudy, Thrissur District, Kerala, India | Athirappilly, Thrissur District, Kerala, India | G39: Approve | H39: New property – verified across sources | L39: +91 94464 04151 | M39: babyranibsnl@gmail.com | N39: BLANK | O39: Guest House | Specialty Lodging | Q39: 10.323819 | R39: 76.394271 | S39: 500 | T39: 10.285 | U39: 76.5694 | V39: The listing mentions Athirappilly, but the map shows the farm-stay near Chalakudy, 20 km west. When text and map disagree, trust where the property physically is. | W39: https://www.keralatourism.org/homestays/aathira-agri-homes/7136
A40: D4-06 | B40: 4 | C40: 6 | D40: Taj Palace & Tower Colaba | E40: The Taj Mahal Palace | F40: Mumbai (Bombay), Maharashtra, India | G40: Alias | H40: Existing Tripadvisor listing – add feed name as alias | O40: Hotel | Q40: 18.9217 | R40: 72.8332 | T40: 18.9217 | U40: 72.8332 | V40: One of the most famous hotels in India — it is obviously on Tripadvisor. Match it to the existing listing.
A41: D4-07 | B41: 4 | C41: 7 | D41: Leopold Cafe & Stay | E41: Leopold Cafe | F41: Mumbai (Bombay), Maharashtra, India | G41: Reject | H41: Not an accommodation | O41: N/A | Q41: 18.9227 | R41: 72.8317 | T41: 18.9227 | U41: 72.8317 | V41: Leopold Cafe is a famous restaurant and bar. "& Stay" in the feed doesn't make it lodging — there are no guest rooms. Reject.
...

Sheet Hotel List
A1: Hotels used in the built-in days
A3: Day | B3: Case | C3: Property (correct name) | D3: Parent | E3: Correct action | F3: Real / invented
A4: 1 | B4: D1-01 | C4: Snow Moon Homestay | D4: Munnar, Idukki District, Kerala, India | E4: Approve | F4: Real – Kerala Tourism homestay
A5: 1 | B5: D1-02 | C5: Green Horizon Homestay | D5: Kochi (Cochin), Ernakulam District, Kerala, India | E5: Approve | F5: Real – Kerala Tourism homestay
A6: 1 | B6: D1-03 | C6: Kerala Spices Homestay | D6: Kumily (Thekkady), Idukki District, Kerala, India | E6: Approve | F6: Real – Kerala Tourism homestay
A7: 1 | B7: D1-04 | C7: Bougainvillea Homestay | D7: Varkala, Thiruvananthapuram District, Kerala, India | E7: Approve | F7: Real – Kerala Tourism homestay
A8: 1 | B8: D1-05 | C8: Ananda Homestay | D8: Ambalavayal, Wayanad District, Kerala, India | E8: Approve | F8: Real – Kerala Tourism homestay
A9: 1 | B9: D1-06 | C9: Royal Mist | D9: Munnar, Idukki District, Kerala, India | E9: Approve | F9: Real – Kerala Tourism homestay
A10: 1 | B10: D1-07 | C10: Thayil Kadaloram Homestay | D10: Kovalam, Thiruvananthapuram District, Kerala, India | E10: Approve | F10: Real – Kerala Tourism homestay
A11: 1 | B11: D1-08 | C11: Kumarakom Lake Resort | D11: Kumarakom, Kottayam District, Kerala, India | E11: Alias | F11: Real – already on Tripadvisor
A12: 1 | B12: D1-09 | C12: Mattancherry Palace | D12: Kochi (Cochin), Ernakulam District, Kerala, India | E12: Reject | F12: Real – not lodging
A13: 1 | B13: D1-10 | C13: Amberleaf Spice Court | D13: Kumily (Thekkady), Idukki District, Kerala, India | E13: Reject | F13: Invented (training only)
A14: 2 | B14: D2-01 | C14: The Haven Munnar | D14: Munnar, Idukki District, Kerala, India | E14: Approve | F14: Real – Kerala Tourism homestay
A15: 2 | B15: D2-02 | C15: Linn View Home Stay Munnar | D15: Munnar, Idukki District, Kerala, India | E15: Approve | F15: Real – Kerala Tourism homestay
... A53: 5 | B53: D5-10 | C53: Azure Pearl Villas | D53: Kovalam, Thiruvananthapuram District, Kerala, India | E53: Tier 2 | F53: Invented (training only)

Sheet Action Mix
A1: Correct-action mix per day
A3: Action | B3: Day 1 | C3: Day 2 | D3: Day 3 | E3: Day 4 | F3: Day 5 | G3: Total
A4: Approve | B4: =COUNTIFS('Answer Key'!$G$5:$G$54,$A4,'Answer Key'!$B$5:$B$54,1) -> 7 | C4: =COUNTIFS('Answer Key'!$G$5:$G$54,$A4,'Answer Key'!$B$5:$B$54,2) -> 7 | D4: =COUNTIFS('Answer Key'!$G$5:$G$54,$A4,'Answer Key'!$B$5:$B$54,3) -> 6 | E4: =COUNTIFS('Answer Key'!$G$5:$G$54,$A4,'Answer Key'!$B$5:$B$54,4) -> 5 | F4: =COUNTIFS('Answer Key'!$G$5:$G$54,$A4,'Answer Key'!$B$5:$B$54,5) -> 5 | G4: =SUM(B4:F4) -> 30
A5: Alias | B5: =COUNTIFS('Answer Key'!$G$5:$G$54,$A5,'Answer Key'!$B$5:$B$54,1) -> 1 | C5: =COUNTIFS('Answer Key'!$G$5:$G$54,$A5,'Answer Key'!$B$5:$B$54,2) -> 1 | D5: =COUNTIFS('Answer Key'!$G$5:$G$54,$A5,'Answer Key'!$B$5:$B$54,3) -> 1 | E5: =COUNTIFS('Answer Key'!$G$5:$G$54,$A5,'Answer Key'!$B$5:$B$54,4) -> 1 | F5: =COUNTIFS('Answer Key'!$G$5:$G$54,$A5,'Answer Key'!$B$5:$B$54,5) -> 1 | G5: =SUM(B5:F5) -> 5
A6: Reject | B6: =COUNTIFS('Answer Key'!$G$5:$G$54,$A6,'Answer Key'!$B$5:$B$54,1) -> 2 | C6: =COUNTIFS('Answer Key'!$G$5:$G$54,$A6,'Answer Key'!$B$5:$B$54,2) -> 1 | D6: =COUNTIFS('Answer Key'!$G$5:$G$54,$A6,'Answer Key'!$B$5:$B$54,3) -> 2 | E6: =COUNTIFS('Answer Key'!$G$5:$G$54,$A6,'Answer Key'!$B$5:$B$54,4) -> 2 | F6: =COUNTIFS('Answer Key'!$G$5:$G$54,$A6,'Answer Key'!$B$5:$B$54,5) -> 3 | G6: =SUM(B6:F6) -> 10
A7: Tier 1 | B7: =COUNTIFS('Answer Key'!$G$5:$G$54,$A7,'Answer Key'!$B$5:$B$54,1) -> 0 | C7: =COUNTIFS('Answer Key'!$G$5:$G$54,$A7,'Answer Key'!$B$5:$B$54,2) -> 0 | D7: =COUNTIFS('Answer Key'!$G$5:$G$54,$A7,'Answer Key'!$B$5:$B$54,3) -> 0 | E7: =COUNTIFS('Answer Key'!$G$5:$G$54,$A7,'Answer Key'!$B$5:$B$54,4) -> 0 | F7: =COUNTIFS('Answer Key'!$G$5:$G$54,$A7,'Answer Key'!$B$5:$B$54,5) -> 0 | G7: =SUM(B7:F7) -> 0
A8: Tier 2 | B8: =COUNTIFS('Answer Key'!$G$5:$G$54,$A8,'Answer Key'!$B$5:$B$54,1) -> 0 | C8: =COUNTIFS('Answer Key'!$G$5:$G$54,$A8,'Answer Key'!$B$5:$B$54,2) -> 1 | D8: =COUNTIFS('Answer Key'!$G$5:$G$54,$A8,'Answer Key'!$B$5:$B$54,3) -> 1 | E8: =COUNTIFS('Answer Key'!$G$5:$G$54,$A8,'Answer Key'!$B$5:$B$54,4) -> 2 | F8: =COUNTIFS('Answer Key'!$G$5:$G$54,$A8,'Answer Key'!$B$5:$B$54,5) -> 1 | G8: =SUM(B8:F8) -> 5
A9: Defer | B9: =COUNTIFS('Answer Key'!$G$5:$G$54,$A9,'Answer Key'!$B$5:$B$54,1) -> 0 | C9: =COUNTIFS('Answer Key'!$G$5:$G$54,$A9,'Answer Key'!$B$5:$B$54,2) -> 0 | D9: =COUNTIFS('Answer Key'!$G$5:$G$54,$A9,'Answer Key'!$B$5:$B$54,3) -> 0 | E9: =COUNTIFS('Answer Key'!$G$5:$G$54,$A9,'Answer Key'!$B$5:$B$54,4) -> 0 | F9: =COUNTIFS('Answer Key'!$G$5:$G$54,$A9,'Answer Key'!$B$5:$B$54,5) -> 0 | G9: =SUM(B9:F9) -> 0
A10: Total | B10: =SUM(B4:B9) -> 10 | C10: =SUM(C4:C9) -> 10 | D10: =SUM(D4:D9) -> 10 | E10: =SUM(E4:E9) -> 10 | F10: =SUM(F4:F9) -> 10 | G10: =SUM(G4:G9) -> 50
